<testsuites>
    <testsuite failures="3" errors="1" skipped="1" tests="6" time="15.5" name="[ASSIGNTESTSUITE] Suite">
        <!-- Passed test -->
        <testcase classname="[ASSIGNTESTSUITE] Suite" name="[C101] test successful operation" time="2.1"/>
        
        <!-- Failed test 1 -->
        <testcase classname="[ASSIGNTESTSUITE] Suite" name="[C102] test failed validation" time="1.5">
            <failure type="AssertionError" message="Validation failed">
                Expected validation to pass, but it failed with error: Invalid input
            </failure>
        </testcase>
        
        <!-- Failed test 2 -->
        <testcase classname="[ASSIGNTESTSUITE] Suite" name="[C103] test failed network call" time="3.2">
            <failure type="NetworkError" message="Connection timeout">
                Network call failed after 30 seconds timeout
            </failure>
        </testcase>
        
        <!-- Error test -->
        <testcase classname="[ASSIGNTESTSUITE] Suite" name="[C104] test error exception" time="0.8">
            <error type="RuntimeError" message="Unexpected runtime error">
                An unexpected runtime error occurred during test execution
            </error>
        </testcase>
        
        <!-- Failed test 3 -->
        <testcase classname="[ASSIGNTESTSUITE] Suite" name="[C105] test failed assertion" time="1.9">
            <failure type="AssertionError" message="Assertion failed">
                Expected value 'expected' but got 'actual'
            </failure>
        </testcase>
        
        <!-- Skipped test -->
        <testcase classname="[ASSIGNTESTSUITE] Suite" name="[C106] test skipped feature" time="0.0">
            <skipped type="pytest.skip" message="Feature not implemented"/>
        </testcase>
    </testsuite>
</testsuites>
